Workbook
Name typology: #REF!
Name UNITS: #REF!
Name typology: Dropdowns!$K$4:$K$12
Name structure: Dropdowns!$R$5:$R$11
Name ORT: Dropdowns!$W$4:$W$11
Name countries: Dropdowns!$D$4:$D$252
Name GBDI_L3: BEC_openBDF!$C$2:$C$90
Name GBDI_L5: BEC_openBDF!$E$2:$E$90
Name GBDI_L4: BEC_openBDF!$D$2:$D$90
Name roof: Dropdowns!$AF$4:$AF$7
Name materials: Dropdowns!$AG$38:$AG$56
Name projectype: #REF!
Name CLIMATE: Dropdowns!$I$4:$I$17
Name SOURCE: #REF!
Name SOURCE: Dropdowns!$AI$4:$AI$10
Name structuretype: #REF!
Name UNITS: Dropdowns!$B$4:$B$5
Name countries: 'Attribute Translator'!$A$7:$A$255
Name seismic: #REF!
Name roof: #REF!
Name ORT: #REF!
Name BIOGENIC: Dropdowns!$AB$4:$AB$8
Name GBDI_L2: BEC_openBDF!$B$1:$B$90
Name seismic: #REF!
Name projectype: Dropdowns!$C$4:$C$7
Name lcamodel: #REF!
Name structuretype: Dropdowns!$V$4:$V$5
Name lcamodel: Dropdowns!$AA$4:$AA$7
Name BIOGENIC: #REF!
Name materials: #REF!
Name structure: #REF!
Name CLIMATE: #REF!

Sheet C.log
A1: Change ID | B1: Sheet name | C1: Cell (row, column) | D1: User | E1: Change type | F1: Status | G1: Old input | H1: New input | I1: Notes
A2: 001 | B2: Info (ReadMe) | C2: B3C5 | D2: Zuhaib Batra | E2: Added | F2: Completed
A3: 002 | B3: Admin_info | D3: Martin Röck | E3: Edited | F3: Completed | I3: Merged the sheets admin_info, building_info, LCA_methodology into one joint sheet "General information"
A4: 003 | B4: Admin_info | D4: Martin Röck | E4: Edited | F4: Completed | I4: Activated the filtering function for the "General information" attributes
B5: Admin_info | D5: Martin Röck | E5: Edited | F5: Completed | I5: Adjusted the min/rec/opt settings in "General information"
D6: Martin Röck | E6: Edited | F6: Completed | I6: Edited colors of sheets to align with documentation requirement colors (green = min/mandatory; blue = recommended; grey = optional)

Sheet Info (ReadMe)
A1: Open Building Data Format (OpenBDF)
A2: Version | B2: Internal Working Draft
A3: Date | B3: 45720
A4: Authors | B4: Zuhaib Batra, Nicole Di Santo, Martin Röck
A5: Contact | B5: martin.roeck@riselabs.at
A9: Documentation Requirements
A10: Hidden Cells | B10: Not for the user, only for internal use
A11: Automatic | B11: Read‑only information for display.
A12: Minimum Required | B12: Essential information for compliance with regulations and standards.
A13: Recommended | B13: Recommended information to provide additional insights that are useful for specific projects or detailed analyses.
A14: Optional | B14: Other optional information relevant to other considerations.
A17: Sheet Name Colour
A18: Sheet | B18: OpenBDF SLIM VERSION | C18: OpenBDF FULL VERSION (as a Template from the Platform)
A19: Info (ReadMe) | B19: TRUE | C19: TRUE
A20: General Information | B20: TRUE | C20: TRUE
A21: Materials Database (platform) | B21: FALSE | C21: TRUE
A22: Building Elements Database (platform) | B22: FALSE | C22: TRUE
A23: Building Bill of Materials (platform) | B23: FALSE | C23: TRUE
A24: Building Bill of Materials SLIM | B24: TRUE | C24: TRUE
A25: Building LCA Results Wide | B25: TRUE | C25: TRUE
A26: Building LCA Results_Tall (platform - ONLY PYTHON) | B26: FALSE | C26: TRUE
A27: Dropdowns | B27: FALSE | C27: FALSE
A30: User input (Data and Model)
A31: Type of Cell | B31: Colour Code | C31: Meaning
A32: User Input | B32: Yellow | C32: Editable fields
A33: Error / Missing Value | B33: Red | C33: Needs user attention
A34: Display | B34: Light Blue | C34: Read‑only display
A35: Excluded | B35: Black | C35: Not Applicable
A36: Instructions | B36: Orange | C36: Not editable
A39: Changelog (add new versions on top)
A41: v2.0.1 | B41: 2nd generation OpenBDF
B42: Updated OpenBDF inventory and LCIA data structure
B43: Revised the building level attribute
A47: OpenBDF_v2.0.1_Draft_19.02.2026_MR02_Slim
A52: Definiton

Sheet General Information
A1: Group | B1: Sub-group | C1: Attribute Name | D1: Field CODE | E1: Description | F1: Datatype assigned to the indicator | G1: Constraint | H1: Units | I1: Requirements | J1: Inputs | K1: Units | L1: Reference Formats | O1: Examples
E2: Description of the attribute | F2: Datatype assigned to the indicator | H2: Unit associated with the indicator | I2: Follow documentation requirements! | J2: Enter/select values of your project here. | K2: Enter the units where applicable. | L2: ECHO | M2: CarbEnMats | N2: CLF | O2: These examples are for your reference only.
A3: Project | B3: Administrative data | C3: Project ID | D3: project_id | E3: Unique ID assigned to this specific project. | F3: String (Free text) | G3: string < 200 characters | H3: none | I3: Automatic | L3: TRUE | M3: TRUE | N3: FALSE | O3: e.g. ABC1234
A4: Project | B4: Administrative data | C4: Project Unit System | D4: project_units | E4: Unit system used in the assessment (Imperial Units System (IP, USA); International Units System (SI)). | F4: String (Free text) | G4: dropdown | H4: none | I4: Minimum Required | J4: Metric, International Units System (SI) | L4: TRUE | M4: FALSE | N4: TRUE | O4: Metric, International Units System (SI)
A5: Project | B5: Administrative data | C5: Project Name | D5: project_name | E5: Name of the project (can be anonymized). | F5: String (Free text) | G5: string < 200 characters | H5: none | I5: Recommended | L5: TRUE | M5: FALSE | N5: TRUE | O5: e.g. Brilliant Group Hotel
A6: Project | B6: Administrative data | C6: Project Description | D6: project_description | E6: A general description of the project focusing on its use, function, and extent of work. | F6: String (Free text) | G6: string < 500 characters | H6: none | I6: Optional | L6: FALSE | M6: FALSE | N6: TRUE | O6: e.g. A new hotel on the harbour
A7: Project | B7: Administrative data | C7: Project Construction Type | D7: project_construction_type | E7: New construction, Minor renovation, Major renovation | F7: String (Free text) | G7: dropdown | H7: none | I7: Minimum Required | J7: New construction | L7: TRUE | M7: TRUE | N7: TRUE | O7: New construction
A8: Project | B8: Administrative data | C8: Country | D8: project_country | E8: Country where the project is located. | F8: String (Free text) | G8: dropdown | H8: none | I8: Minimum Required | J8: Argentina | L8: TRUE | M8: TRUE | N8: TRUE | O8: Afghanistan
A9: Project | B9: Administrative data | C9: City | D9: project_city | E9: City where the project is located. | F9: String (Free text) | G9: string < 200 characters | H9: none | I9: Minimum Required | L9: TRUE | M9: FALSE | N9: TRUE | O9: e.g. Potsdam
A10: Project | B10: Administrative data | C10: State | D10: project_state | E10: State, province, or country subdivision where the project is located. | F10: String (Free text) | G10: string < 200 characters | H10: none | I10: Recommended | L10: TRUE | M10: FALSE | N10: TRUE | O10: e.g. Brandenburg
A11: Project | B11: Administrative data | C11: Address | D11: project_address | E11: Address of the project. | F11: String (Free text) | G11: string < 200 characters | H11: none | I11: Recommended | L11: TRUE | M11: FALSE | N11: TRUE | O11: e.g. Voorstrasse 20, 1417 Potsdam
A12: Project | B12: Administrative data | C12: Owner / Client Name | D12: project_owner_name | E12: Individual or entity that owns the project. | F12: String (Free text) | G12: string < 200 characters | H12: none | I12: Optional | L12: TRUE | M12: FALSE | N12: TRUE | O12: e.g. Mr. Brown Alter
A13: Project | B13: Administrative data | C13: Date of Assessment | D13: project_date_assessment | E13: Date of the life-cycle assessment conducted by the assessor. | F13: Numerical [integer] | G13: ISO date | H13: # | I13: Minimum Required | J13: 46064 | L13: TRUE | M13: FALSE | N13: FALSE | O13: 46064
A14: Project | B14: Administrative data | C14: Third Party Verified | D14: project_third_verified | E14: Is the project LCA verified by a third-party? | F14: Boolean [Yes/NO] | G14: boolean | H14: none | I14: Minimum Required | J14: Yes | L14: FALSE | M14: FALSE | N14: FALSE | O14: Yes
A15: Project | B15: Administrative data | C15: Third Party Verifier Name | D15: project_third_verifier_name | E15: Name of the third-party verification person/organisation. | F15: String (Free text) | G15: string < 200 characters | H15: none | I15: Recommended | L15: FALSE | M15: FALSE | N15: FALSE | O15: e.g. Pullmann Consultants, Zurich
A16: Project | B16: Administrative data | C16: Verification Date | D16: project_verification_date | E16: Date of the verification of the assessment by third-party. | F16: Numerical [integer] | G16: ISO date | H16: # | I16: Optional | J16: 46060 | L16: FALSE | M16: FALSE | N16: FALSE | O16: 46060
A17: Project | B17: Administrative data | C17: Certification | D17: project_certification | E17: Type of sustainability certification being applied for the project. | F17: String (Free text) | G17: dropdown | H17: none | I17: Minimum Required | J17: Yes | L17: FALSE | M17: TRUE | N17: FALSE | O17: e.g. LEED
A18: Project | B18: Administrative data | C18: Certification Name | D18: project_certification_name | E18: Type of sustainability certification being applied for the project. | F18: String (Free text) | G18: string < 200 characters | H18: none | I18: Recommended | L18: FALSE | M18: TRUE | N18: FALSE | O18: e.g. LEED
A19: Project | B19: Administrative data | C19: Certification Application Date | D19: pooject_certification_date | E19: Date of application for the sustainability certification for the project. | F19: Numerical [integer] | G19: ISO date | H19: # | I19: Recommended | J19: 46060 | L19: FALSE | M19: FALSE | N19: FALSE | O19: 46061
A20: Project | B20: Administrative data | C20: Certification Application ID | D20: project_certification_id | E20: Unique ID assigned to the certification application. | F20: String (Free text) | G20: string < 200 characters | H20: none | I20: Optional | L20: FALSE | M20: FALSE | N20: FALSE | O20: e.g. ABC1234
A21: Project | B21: Administrative data | C21: Project Permit Application Date | D21: project_ardpit_date | E21: Date of application for construction ardpit. | F21: String (Free text) | G21: string < 200 characters | H21: none | I21: Recommended | J21: 46060 | L21: FALSE | M21: TRUE | N21: FALSE | O21: 46061
A22: Project | B22: Administrative data | C22: Project Permit ID | D22: project_ardpit_id | E22: Unique ID of the project ardpit. | F22: String (Free text) | G22: string < 200 characters | H22: none | I22: Recommended | L22: FALSE | M22: FALSE | N22: FALSE | O22: e.g. ABC1234
A23: Project | B23: Administrative data | C23: Project Total Plot Area | D23: project_plot_area | E23: Total plot area of the project according to national standard. | F23: Numerical [decimal] | G23: numerical | H23: m2 | I23: Recommended | K23: m2 | L23: TRUE | M23: FALSE | N23: FALSE | O23: e.g. 500
A24: Project | B24: Administrative data | C24: No. of Buildings | D24: project_no_of_buildings | E24: Total number of buildings in the project. | F24: Numerical [integer] | G24: numerical | H24: # | I24: Minimum Required | L24: FALSE | M24: FALSE | N24: TRUE | O24: e.g. 5
A25: Project | B25: Administrative data | C25: Project Phase | D25: project_phase | E25: Stage of the project when LCA is conducted (according to national standard) | F25: String (Free text) | G25: dropdown | H25: none | I25: Minimum Required | J25: Preliminary studies | L25: TRUE | M25: FALSE | N25: FALSE | O25: Preliminary studies
A26: Project | B26: Administrative data | C26: Project Design Start Date | D26: project_design_start_date | E26: Project design start date. | F26: Numerical [integer] | G26: ISO date | H26: # | I26: Recommended | J26: 46060 | L26: TRUE | M26: FALSE | N26: FALSE | O26: 46061
A27: Project | B27: Project Stakeholders | C27: Construction Company Name | D27: project_construction_company_name | E27: Name of the company constructing the project. | F27: String (Free text) | G27: string < 200 characters | H27: none | I27: Optional | L27: FALSE | M27: FALSE | N27: FALSE | O27: e.g. Terranova Construction Company
A28: Project | B28: Project Stakeholders | C28: Construction Company Address | D28: project_construction_company_address | E28: Physical location of the construction company. | F28: String (Free text) | G28: string < 200 characters | H28: none | I28: Optional | L28: FALSE | M28: FALSE | N28: FALSE | O28: e.g. Seebachstrasse 21, 5100 Zurich
A29: Project | B29: Project Stakeholders | C29: Contractor Name | D29: project_contractor_name | E29: Name of the contractor executing the construction. | F29: String (Free text) | G29: string < 200 characters | H29: none | I29: Optional | L29: TRUE | M29: FALSE | N29: FALSE | O29: e.g. Regionale Contractors
A30: Project | B30: Project Stakeholders | C30: Architect/ Engineer | D30: project_architect_engineer_name | E30: Name of the architect/engineer appointed on the project | F30: String (Free text) | G30: string < 200 characters | H30: none | I30: Optional | L30: TRUE | M30: FALSE | N30: FALSE | O30: e.g. Peter Sylon
A31: Project | B31: Project Stakeholders | C31: Structural Engineer | D31: project_structural_engineer_name | E31: Name of the engineer appointed on the project | F31: String (Free text) | G31: string < 200 characters | H31: none | I31: Optional | L31: TRUE | M31: FALSE | N31: FALSE | O31: e.g. Peter Sylon
A32: Project | B32: Project Stakeholders | C32: MEP Engineer | D32: project_mep_engineer_name | E32: Name of the MEP Engineer appointed on the project | F32: String (Free text) | G32: string < 200 characters | H32: none | I32: Optional | L32: TRUE | M32: FALSE | N32: FALSE | O32: e.g. Peter Sylon
A33: Project | B33: Project Stakeholders | C33: Environmental Consultant Company | D33: project_environmental_consultant_company | E33: Name of the company conducting the LCA assessment | F33: String (Free text) | G33: string < 200 characters | H33: none | I33: Optional | L33: TRUE | M33: FALSE | N33: FALSE | O33: e.g. Environmental Design Consultants
A34: Project | B34: Project Stakeholders | C34: Environmental Assessor Name | D34: project_environmental_assessor_name | E34: Name of the environmental assessor | F34: String (Free text) | G34: string < 200 characters | H34: none | I34: Optional | L34: TRUE | M34: FALSE | N34: FALSE | O34: e.g. Thomas Casper
A35: Project | B35: Project Stakeholders | C35: Environmental Assessor Contact | D35: project_environmental_assessor_contact | E35: Contact details of the Environmental assessor (e.g. email, phone) | F35: String (Free text) | G35: string < 200 characters | H35: none | I35: Optional | L35: TRUE | M35: TRUE | N35: FALSE | O35: e.g. email or phone number
A36: Building | B36: Building data (general) | C36: Building ID | D36: building_id | E36: Assigned identifier for the building renovated/constructed. | F36: String (Free text) | G36: string < 200 characters | H36: none | I36: Automatic | L36: FALSE | M36: FALSE | N36: FALSE | O36: e.g. ABC1234
A37: Building | B37: Building data (general) | C37: Building GPS Coordinates | D37: building_gps_coordinates | E37: Latitude and longitude of the building project (decimal degrees) | F37: Numerical [decimal] | G37: numerical | H37: # | I37: Recommended | L37: FALSE | M37: FALSE | N37: FALSE | O37: e.g. 41.40338, 2.17403
A38: Building | B38: Building data (general) | C38: ASHRAE Geographic Climate Zone Typologies | D38: building_geographic_climate_zone | E38: Classification of the area's climate based on ASHRAE classification | F38: String (Free text) | G38: dropdown | H38: none | I38: Minimum Required | J38: 2A (Hot - Humid) | L38: TRUE | M38: TRUE | N38: FALSE | O38: 2A (Hot - Humid)
A39: Building | B39: Building data (general) | C39: Altitude | D39: building_altitude | E39: Elevation of the project site above sea level | F39: Numerical [decimal] | G39: numerical | H39: m | I39: Recommended | K39: m | L39: FALSE | M39: FALSE | N39: FALSE | O39: e.g. 200m or 400 ft.
A40: Building | B40: Building data (general) | C40: Seismic Zone | D40: building_seismic_zone | E40: Classification of the area's seismic activity level according to national standard | F40: String (Free text) | G40: dropdown | H40: none | I40: Recommended | J40: SDC A: Minor expected ground shaking. | L40: FALSE | M40: TRUE | N40: TRUE | O40: SDC A: Minor expected ground shaking.
...

Sheet Materials Database
A1: Attribute | B1: Material Group | C1: Material Name (or ID) | D1: Material Name from EPD database | E1: EPD Database Name | F1: EPD Database Link | G1: Declared Amount | H1: Declared Unit | I1: Reference Service life | J1: Material Density (kg/m3) | K1: Material Weight (kg) | L1: Material Thickness | M1: Material Volume | N1: Type of EPD | O1: LCA stages | P1: LCA module
A2: Description | B2: Material classification / reference | C2: The specific, user-defined identifier for the material. | D2: The precise material designation as cataloged in the associated Environmental Product Declaration (EPD) database. | E2: The nomenclature of the specific Environmental Product Declaration (EPD) dataset used. | F2: The URL of the specific Environmental Product Declaration (EPD) dataset used. | G2: Declared amount in EPD | H2: Declared unit in EPD | I2: Declared reference service life | J2: The mass per unit volume of the custom material. | K2: The absolute physical mass of the custom material. | L2: Declared thickness | M2: Declared volume | N2: List and explanation of the life cycle declared in the EPD. | O2: Life cycle stage(s) of the material (e.g. A1-A3, B1-B4, C2-C4, D) | P2: Life cycle module(s) of the material (e.g. A1, A2, B2, D)
A3: Datatype | B3: String (Free text) | C3: String (Free text) | D3: Categorical (Predefined) | E3: String (Free text) | F3: String (Free text) | G3: Numerical [decimal] | H3: String (Free text) | I3: Numerical [decimal] | J3: Numerical [decimal] | K3: Numerical [decimal] | L3: Numerical [decimal] | M3: Numerical [decimal] | N3: String (Free text) | O3: String (Free text) | P3: String (Free text)
A4: Constraint | B4: dropdown | C4: string < 200 characters | D4: dropdown | E4: string < 200 characters | F4: string < 200 characters | G4: numerical | H4: dropdown | I4: numerical | J4: numerical | K4: numerical | L4: numerical | M4: numerical | N4: dropdown | O4: dropdown | P4: dropdown
A5: Unit | B5: none | C5: none | D5: none | E5: none | F5: none | G5: # | H5: none | I5: # | J5: kg/m3 | K5: kg | L5: (mm) | M5: (m3) | N5: none | O5: none | P5: none
A6: Requirements | B6: Minimum Required | C6: Minimum Required | D6: Recommended | E6: Recommended | F6: Optional | G6: Minimum Required | H6: Minimum Required | I6: Minimum Required | J6: Minimum Required | K6: Minimum Required | L6: Minimum Required | M6: Minimum Required | N6: Minimum Required | O6: Minimum Required | P6: Minimum Required
A7: Instructions | B7: Enter your custom material group. Maximum 200 characters. ↓ | C7: Enter your custom material name. Maximum 200 characters. ↓ | D7: Enter the exact material name as it appears in the EPD database. Maximum 200 characters. ↓ | E7: Enter the name of the EPD dataset. Maximum 200 characters. ↓ | F7: Enter the name of the EPD dataset or provide a direct link to it. Maximum 200 characters. ↓ | G7: Enter the amount of the material from the EPD. ↓ | H7: Enter the unit of the material from the EPD. ↓ | I7: Enter the reference service life of the material from the EPD. ↓ | J7: Enter the density of the material in (kg/m³). ↓ | K7: The total weight of the custom material in kilograms (kg). ↓ | L7: The material thickness in millimeters (mm). ↓ | M7: The material volume in cubic meters (m3). ↓
A8: Field CODE | C8: material_name_custom | D8: material_name_database | E8: epd_dataset | F8: epd_dataset_link | J8: custom_material_density
B9: 1 Bio-based materials/1.1 Wood | D9: Gypsum plasterboard | G9: 1 | H9: m2 | I9: 50 | K9: 3.8 | L9: 100 | M9: 0.1 | N9: Cradle to Gate (A1–A3) | O9: A1–A3: Product Stage | P9: A1: Raw Material Supply – Extraction and processing of raw materials.
B233: [End of table - Add rows above]

Sheet Building Elements Database
A1: Attribute | B1: Building ID/Zone ID | C1: Element Class (Tier 1) | D1: Element Class (Tier 2) | E1: Element Class (Tier 3) | F1: Element Class (Tier 4) | G1: Element Name (or ID) | H1: Above/Below Ground | I1: Area of Building Element
A2: Description | B2: Assign Building/Zone ID (similar to attribute in building_info tab) | C2: Primary (top-level) hierarchical category of the custom or national building element classification. | D2: Secondary hierarchical category of the custom or national building element classification. | E2: The tertiary hierarchical category of the custom or national building element classification. | F2: The quaternary (lowest-level) hierarchical category of the custom or national building element classification. | G2: The specific, user-defined identifier for the building element. | H2: Above ground (AG) or below ground (BG) | I2: Enter the surface area of the building element
A3: Datatype | B3: String (Free text) | C3: String (Free text) | D3: String (Free text) | E3: String (Free text) | F3: String (Free text) | G3: String (Free text) | H3: String (Free text) | I3: Numerical [decimal]
A4: Constraint | B4: string < 200 characters | C4: string < 200 characters | D4: string < 200 characters | E4: string < 200 characters | F4: string < 200 characters | G4: string < 200 characters | H4: dropdown | I4: numerical
A5: Unit | B5: none | C5: none | D5: none | E5: none | F5: none | G5: none | H5: none | I5: m2
A6: Requirements | B6: Minimum Required | C6: Minimum Required | D6: Minimum Required | E6: Recommended | F6: Optional | G6: Recommended | H6: Minimum Required | I6: Recommended
A7: Instructions | C7: Enter the primary (Tier 1) name of you national element class. Maximum 200 characters. ↓ | D7: Enter the secondary (Tier 2) name for your element class. Maximum 200 characters. ↓ | E7: Enter the tertiary (Tier 3) name for your element class. Maximum 200 characters. ↓ | F7: Enter the quaternary (Tier 4) name for your element class. Maximum 200 characters. ↓ | G7: Enter the custom name of your building element. Maximum 200 characters. ↓ | H7: Select from the dropdown the finished floor level is located above or below the surrounding natural or finished ground level. ↓
A8: Field CODE | C8: bec_custom_tier1 | D8: bec_custom_tier2 | E8: bec_custom_tier3 | F8: bec_custom_tier4 | G8: element_name_custom
C9: 1 Sub-structure | D9: 1.1 Foundations and piling | E9: 1.1.1 Foundations and piling | H9: Above ground | I9: 123
B233: [End of table - Add rows above]

Sheet Building Bill of Materials_FULL
A1: Attribute | B1: Floor level | C1: Above/Below Ground | D1: Element Class (Tier 1) | E1: Element Class (Tier 2) | F1: Element Class (Tier 3) | G1: Element Class (Tier 4) | H1: Element Class Description | I1: OpenBDF Building Element Classification | J1: openBDF Building Element class (T1) | K1: openBDF Building Element class (T2) | L1: openBDF Building Element class (T3) | M1: openBDF Building Element class (T4) | N1: Element Name (or ID) | O1: OpenBDF Common Material Classification | P1: Material Name (or ID) | Q1: Material Name from EPD database | R1: EPD Database Name | S1: EPD Database Link | T1: Service life (years) | U1: Material Quantity (m3) | V1: Material Quantity (m2) | W1: Material Quantity (m) | X1: Material Quantity (count) | Y1: Material Weight (kg) | Z1: Density (kg/m3) | AA1: Share of Layer (%) | AB1: LCA stages | AC1: LCA modules
A2: Description | B2: Storey of the building element. | C2: Position of the finished floor level relative to the natural or finished ground elevation. | D2: Primary (top-level) hierarchical category of the custom or national building element classification. | E2: Secondary hierarchical category of the custom or national building element classification. | F2: The tertiary hierarchical category of the custom or national building element classification. | G2: The quaternary (lowest-level) hierarchical category of the custom or national building element classification. | H2: The Description of the custom or national element class. | I2: The highest applicable tier of the building element within the standardized openBDF framework. | J2: The equivalent openBDF Tier 1 (primary) classification mapped to the custom element. | K2: The equivalent openBDF Tier 2 (secondary) classification mapped to the custom element. | L2: The equivalent openBDF Tier 3 (tertiary) classification mapped to the custom element. | M2: The equivalent openBDF Tier 4 (quaternary) classification mapped to the custom element. | N2: The specific, user-defined identifier for the building element. | O2: The corresponding material classification from the standardized openBDF taxonomy. | P2: The specific, user-defined identifier for the material. | Q2: The precise material designation as cataloged in the associated Environmental Product Declaration (EPD) database. | R2: The nomenclature of the specific Environmental Product Declaration (EPD) dataset used. | S2: The URL of the specific Environmental Product Declaration (EPD) dataset used. | T2: Declared reference service life | U2: The measured scalar amount (volume) of the custom material. | V2: The measured scalar amount (area) of the custom material. | W2: The measured scalar amount (length) of the custom material. | X2: The measured scalar amount (count) of the custom material. | Y2: The absolute physical mass of the custom material. | Z2: The mass per unit volume of the custom material. | AA2: The share of layer in the composition of the building element. | AB2: Life cycle stage(s) of the material (e.g. A1-A3, B1-B4, C2-C4, D) | AC2: Life cycle module(s) of the material (e.g. A1, A2, B2, D)
A3: Datatype | B3: Numerical [integer] | C3: Categorical (Predefined) | D3: String (Free text) | E3: String (Free text) | F3: String (Free text) | G3: String (Free text) | H3: String (Free text) | I3: Categorical (Predefined) | N3: String (Free text) | O3: Categorical (Predefined) | P3: String (Free text) | Q3: Categorical (Predefined) | R3: String (Free text) | S3: String (Free text) | T3: Numerical [decimal] | U3: Numerical [decimal] | V3: Numerical [decimal] | W3: Numerical [decimal] | X3: Numerical [decimal] | Y3: Numerical [decimal] | Z3: Numerical [decimal] | AA3: Numerical [decimal] | AB3: Categorical (Predefined) | AC3: Categorical (Predefined)
A4: Constraint | B4: numerical | C4: dropdown | D4: string < 200 characters | E4: string < 200 characters | F4: string < 200 characters | G4: string < 200 characters | H4: string < 200 characters | I4: dropdown | J4: string < 200 characters | K4: string < 200 characters | L4: string < 200 characters | M4: string < 200 characters | N4: string < 200 characters | O4: dropdown | P4: string < 200 characters | Q4: dropdown | R4: string < 200 characters | S4: string < 200 characters | T4: numerical | U4: numerical | V4: numerical | W4: numerical | X4: numerical | Y4: numerical | Z4: numerical | AA4: numerical | AB4: dropdown | AC4: dropdown
A5: Unit | B5: none | C5: none | D5: none | E5: none | F5: none | G5: none | H5: none | I5: none | J5: none | K5: none | L5: none | M5: none | N5: none | O5: none | P5: none | Q5: none | R5: none | S5: none | T5: # | U5: # | V5: # | W5: # | X5: # | Y5: kg | Z5: kg/m3 | AA5: % | AB5: none | AC5: none
A6: Requirements | B6: Minimum Required | C6: Minimum Required | D6: Minimum Required | E6: Minimum Required | F6: Recommended | G6: Optional | H6: Recommended | I6: Recommended | J6: Automatic | K6: Automatic | L6: Automatic | M6: Automatic | N6: Recommended | O6: Minimum Required | P6: Minimum Required | Q6: Recommended | R6: Optional | S6: Optional | T6: Optional | U6: Recommended | V6: Recommended | W6: Recommended | X6: Recommended | Y6: Minimum Required | Z6: Minimum Required | AA6: Recommended | AB6: Minimum Required | AC6: Recommended
A7: User Instructions | B7: Enter the floor level with reference ground floor = 0 floor level above = + number floor level below = - number. ↓ | C7: Select from the dropdown the finished floor level is located above or below the surrounding natural or finished ground level. ↓ | D7: Enter the primary (Tier 1) name of you national element class. Maximum 200 characters. ↓ | E7: Enter the secondary (Tier 2) name for your element class. Maximum 200 characters. ↓ | F7: Enter the tertiary (Tier 3) name for your element class. Maximum 200 characters. ↓ | G7: Enter the quaternary (Tier 4) name for your element class. Maximum 200 characters. ↓ | H7: Provide the description of the element class. Maximum 200 characters. ↓ | I7: Select the highest openBDF Tier that corresponds to your building element from the dropdown menu. ↓ | J7: No action needed. This automatically displays the equivalent openBDF Tier 1 classification. | K7: No action needed. This automatically displays the equivalent openBDF Tier 2 classification. | L7: No action needed. This automatically displays the equivalent openBDF Tier 3 classification. | M7: No action needed. This automatically displays the equivalent openBDF Tier 4 classification. | N7: Enter the custom name of your building element. Maximum 200 characters. ↓ | O7: Select the openBDF material classification that matches your custom material from the dropdown menu. ↓ | P7: Enter your custom material name. Maximum 200 characters. ↓ | Q7: Enter the exact material name as it appears in the EPD database. Maximum 200 characters. ↓ | R7: Enter the name of the EPD dataset or provide a direct link to it. Maximum 200 characters. ↓ | S7: Enter the name of the EPD dataset or provide a direct link to it. Maximum 200 characters. ↓ | T7: Enter the service life of the custom material. ↓ | U7: Enter the total amount of the custom material. ↓ | V7: Enter the total amount of the custom material. ↓ | W7: Enter the total amount of the custom material. ↓ | X7: Enter the total amount of the custom material. ↓ | Y7: Enter the total weight of the custom material in kilograms (kg) as a decimal number. ↓ | Z7: Enter the density of the custom material in kg/m³ as a decimal number. ↓ | AA7: Enter the share of layer in the building element . ↓ | AB7: Select the life cycle stage of the material. ↓ | AC7: Select the life cycle module of the material. ↓
A8: Field CODE | B8: floor_level | C8: above_below_ground | D8: bec_custom_tier1 | E8: bec_custom_tier2 | F8: bec_custom_tier3 | G8: bec_custom_tier4 | H8: bec_custom_description | I8: bec_openbdf_selection | J8: bec_openbdf_tier1 | K8: bec_openbdf_tier2 | L8: bec_openbdf_tier3 | M8: bec_openbdf_tier4 | N8: element_name_custom | O8: openbdf_material_name | P8: material_name_custom | Q8: material_name_database | R8: lca_dataset | S8: lca_dataset_link | T8: lca_service_life | U8: custom_material_quantity_m3 | V8: custom_material_quantity_m2 | W8: custom_material_quantity_m | X8: custom_material_quantity_count | Y8: custom_material_weight_kg | Z8: custom_material_density | AA8: share_layer | AB8: lca_stages | AC8: lca_module
C9: Above ground | I9: 1.1.1.0 Foundations and piling | J9: =IFERROR(__xludf.DUMMYFUNCTION("IF( $I9="""", """", IF( COLUMN()-9 > (1 + LEN(REGEXEXTRACT($I9,""^[0-9.]+"")) - LEN(SUBSTITUTE(REGEXEXTRACT($I9,""^[0-9.]+""),""."",""""))), """", INDEX( BEC_openBDF!$A:$D, MATCH( $I9, INDEX( BEC"&"_openBDF!$A:$D, 0, (1 + LEN(REGEXEXTRACT($I9,""^[0-9.]+"")) - LEN(SUBSTITUTE(REGEXEXTRACT($I9,""^[0-9.]+""),""."",""""))) ), 0 ), COLUMN()-9 ) ) )"),"1 Sub-structure") -> 1 Sub-structure | K9: =IFERROR(__xludf.DUMMYFUNCTION("IF( $I9="""", """", IF( COLUMN()-9 > (1 + LEN(REGEXEXTRACT($I9,""^[0-9.]+"")) - LEN(SUBSTITUTE(REGEXEXTRACT($I9,""^[0-9.]+""),""."",""""))), """", INDEX( BEC_openBDF!$A:$D, MATCH( $I9, INDEX( BEC"&"_openBDF!$A:$D, 0, (1 + LEN(REGEXEXTRACT($I9,""^[0-9.]+"")) - LEN(SUBSTITUTE(REGEXEXTRACT($I9,""^[0-9.]+""),""."",""""))) ), 0 ), COLUMN()-9 ) ) )"),"1.1 Foundations and piling") -> 1.1 Foundations and piling | L9: =IFERROR(__xludf.DUMMYFUNCTION("IF( $I9="""", """", IF( COLUMN()-9 > (1 + LEN(REGEXEXTRACT($I9,""^[0-9.]+"")) - LEN(SUBSTITUTE(REGEXEXTRACT($I9,""^[0-9.]+""),""."",""""))), """", INDEX( BEC_openBDF!$A:$D, MATCH( $I9, INDEX( BEC"&"_openBDF!$A:$D, 0, (1 + LEN(REGEXEXTRACT($I9,""^[0-9.]+"")) - LEN(SUBSTITUTE(REGEXEXTRACT($I9,""^[0-9.]+""),""."",""""))) ), 0 ), COLUMN()-9 ) ) )"),"1.1.1 Foundations and piling") -> 1.1.1 Foundations and piling | M9: =IFERROR(__xludf.DUMMYFUNCTION("IF( $I9="""", """", IF( COLUMN()-9 > (1 + LEN(REGEXEXTRACT($I9,""^[0-9.]+"")) - LEN(SUBSTITUTE(REGEXEXTRACT($I9,""^[0-9.]+""),""."",""""))), """", INDEX( BEC_openBDF!$A:$D, MATCH( $I9, INDEX( BEC"&"_openBDF!$A:$D, 0, (1 + LEN(REGEXEXTRACT($I9,""^[0-9.]+"")) - LEN(SUBSTITUTE(REGEXEXTRACT($I9,""^[0-9.]+""),""."",""""))) ), 0 ), COLUMN()-9 ) ) )"),"1.1.1.0 Foundations and piling") -> 1.1.1.0 Foundations and piling | O9: 1 Bio-based materials/1.1 Wood | Q9: ='Materials Database'!D9 -> Gypsum plasterboard | U9: 200 | Y9: 1000 | AB9: A1-A3
I10: .. | J10: =IFERROR(__xludf.DUMMYFUNCTION("IF( $I10="""", """", IF( COLUMN()-9 > (1 + LEN(REGEXEXTRACT($I10,""^[0-9.]+"")) - LEN(SUBSTITUTE(REGEXEXTRACT($I10,""^[0-9.]+""),""."",""""))), """", INDEX( BEC_openBDF!$A:$D, MATCH( $I10, INDEX( "&" BEC_openBDF!$A:$D, 0, (1 + LEN(REGEXEXTRACT($I10,""^[0-9.]+"")) - LEN(SUBSTITUTE(REGEXEXTRACT($I10,""^[0-9.]+""),""."",""""))) ), 0 ), COLUMN()-9 ) ) )"),"..") -> .. | K10: =IFERROR(__xludf.DUMMYFUNCTION("IF( $I10="""", """", IF( COLUMN()-9 > (1 + LEN(REGEXEXTRACT($I10,""^[0-9.]+"")) - LEN(SUBSTITUTE(REGEXEXTRACT($I10,""^[0-9.]+""),""."",""""))), """", INDEX( BEC_openBDF!$A:$D, MATCH( $I10, INDEX( "&" BEC_openBDF!$A:$D, 0, (1 + LEN(REGEXEXTRACT($I10,""^[0-9.]+"")) - LEN(SUBSTITUTE(REGEXEXTRACT($I10,""^[0-9.]+""),""."",""""))) ), 0 ), COLUMN()-9 ) ) )"),"..") -> .. | L10: =IFERROR(__xludf.DUMMYFUNCTION("IF( $I10="""", """", IF( COLUMN()-9 > (1 + LEN(REGEXEXTRACT($I10,""^[0-9.]+"")) - LEN(SUBSTITUTE(REGEXEXTRACT($I10,""^[0-9.]+""),""."",""""))), """", INDEX( BEC_openBDF!$A:$D, MATCH( $I10, INDEX( "&" BEC_openBDF!$A:$D, 0, (1 + LEN(REGEXEXTRACT($I10,""^[0-9.]+"")) - LEN(SUBSTITUTE(REGEXEXTRACT($I10,""^[0-9.]+""),""."",""""))) ), 0 ), COLUMN()-9 ) ) )"),"..") -> .. | M10: =IFERROR(__xludf.DUMMYFUNCTION("IF( $I10="""", """", IF( COLUMN()-9 > (1 + LEN(REGEXEXTRACT($I10,""^[0-9.]+"")) - LEN(SUBSTITUTE(REGEXEXTRACT($I10,""^[0-9.]+""),""."",""""))), """", INDEX( BEC_openBDF!$A:$D, MATCH( $I10, INDEX( "&" BEC_openBDF!$A:$D, 0, (1 + LEN(REGEXEXTRACT($I10,""^[0-9.]+"")) - LEN(SUBSTITUTE(REGEXEXTRACT($I10,""^[0-9.]+""),""."",""""))) ), 0 ), COLUMN()-9 ) ) )"),"")
I11: .. | J11: =IFERROR(__xludf.DUMMYFUNCTION("IF( $I11="""", """", IF( COLUMN()-9 > (1 + LEN(REGEXEXTRACT($I11,""^[0-9.]+"")) - LEN(SUBSTITUTE(REGEXEXTRACT($I11,""^[0-9.]+""),""."",""""))), """", INDEX( BEC_openBDF!$A:$D, MATCH( $I11, INDEX( "&" BEC_openBDF!$A:$D, 0, (1 + LEN(REGEXEXTRACT($I11,""^[0-9.]+"")) - LEN(SUBSTITUTE(REGEXEXTRACT($I11,""^[0-9.]+""),""."",""""))) ), 0 ), COLUMN()-9 ) ) )"),"..") -> .. | K11: =IFERROR(__xludf.DUMMYFUNCTION("IF( $I11="""", """", IF( COLUMN()-9 > (1 + LEN(REGEXEXTRACT($I11,""^[0-9.]+"")) - LEN(SUBSTITUTE(REGEXEXTRACT($I11,""^[0-9.]+""),""."",""""))), """", INDEX( BEC_openBDF!$A:$D, MATCH( $I11, INDEX( "&" BEC_openBDF!$A:$D, 0, (1 + LEN(REGEXEXTRACT($I11,""^[0-9.]+"")) - LEN(SUBSTITUTE(REGEXEXTRACT($I11,""^[0-9.]+""),""."",""""))) ), 0 ), COLUMN()-9 ) ) )"),"..") -> .. | L11: =IFERROR(__xludf.DUMMYFUNCTION("IF( $I11="""", """", IF( COLUMN()-9 > (1 + LEN(REGEXEXTRACT($I11,""^[0-9.]+"")) - LEN(SUBSTITUTE(REGEXEXTRACT($I11,""^[0-9.]+""),""."",""""))), """", INDEX( BEC_openBDF!$A:$D, MATCH( $I11, INDEX( "&" BEC_openBDF!$A:$D, 0, (1 + LEN(REGEXEXTRACT($I11,""^[0-9.]+"")) - LEN(SUBSTITUTE(REGEXEXTRACT($I11,""^[0-9.]+""),""."",""""))) ), 0 ), COLUMN()-9 ) ) )"),"..") -> .. | M11: =IFERROR(__xludf.DUMMYFUNCTION("IF( $I11="""", """", IF( COLUMN()-9 > (1 + LEN(REGEXEXTRACT($I11,""^[0-9.]+"")) - LEN(SUBSTITUTE(REGEXEXTRACT($I11,""^[0-9.]+""),""."",""""))), """", INDEX( BEC_openBDF!$A:$D, MATCH( $I11, INDEX( "&" BEC_openBDF!$A:$D, 0, (1 + LEN(REGEXEXTRACT($I11,""^[0-9.]+"")) - LEN(SUBSTITUTE(REGEXEXTRACT($I11,""^[0-9.]+""),""."",""""))) ), 0 ), COLUMN()-9 ) ) )"),"")
I12: .. | J12: =IFERROR(__xludf.DUMMYFUNCTION("IF( $I12="""", """", IF( COLUMN()-9 > (1 + LEN(REGEXEXTRACT($I12,""^[0-9.]+"")) - LEN(SUBSTITUTE(REGEXEXTRACT($I12,""^[0-9.]+""),""."",""""))), """", INDEX( BEC_openBDF!$A:$D, MATCH( $I12, INDEX( "&" BEC_openBDF!$A:$D, 0, (1 + LEN(REGEXEXTRACT($I12,""^[0-9.]+"")) - LEN(SUBSTITUTE(REGEXEXTRACT($I12,""^[0-9.]+""),""."",""""))) ), 0 ), COLUMN()-9 ) ) )"),"..") -> .. | K12: =IFERROR(__xludf.DUMMYFUNCTION("IF( $I12="""", """", IF( COLUMN()-9 > (1 + LEN(REGEXEXTRACT($I12,""^[0-9.]+"")) - LEN(SUBSTITUTE(REGEXEXTRACT($I12,""^[0-9.]+""),""."",""""))), """", INDEX( BEC_openBDF!$A:$D, MATCH( $I12, INDEX( "&" BEC_openBDF!$A:$D, 0, (1 + LEN(REGEXEXTRACT($I12,""^[0-9.]+"")) - LEN(SUBSTITUTE(REGEXEXTRACT($I12,""^[0-9.]+""),""."",""""))) ), 0 ), COLUMN()-9 ) ) )"),"..") -> .. | L12: =IFERROR(__xludf.DUMMYFUNCTION("IF( $I12="""", """", IF( COLUMN()-9 > (1 + LEN(REGEXEXTRACT($I12,""^[0-9.]+"")) - LEN(SUBSTITUTE(REGEXEXTRACT($I12,""^[0-9.]+""),""."",""""))), """", INDEX( BEC_openBDF!$A:$D, MATCH( $I12, INDEX( "&" BEC_openBDF!$A:$D, 0, (1 + LEN(REGEXEXTRACT($I12,""^[0-9.]+"")) - LEN(SUBSTITUTE(REGEXEXTRACT($I12,""^[0-9.]+""),""."",""""))) ), 0 ), COLUMN()-9 ) ) )"),"..") -> .. | M12: =IFERROR(__xludf.DUMMYFUNCTION("IF( $I12="""", """", IF( COLUMN()-9 > (1 + LEN(REGEXEXTRACT($I12,""^[0-9.]+"")) - LEN(SUBSTITUTE(REGEXEXTRACT($I12,""^[0-9.]+""),""."",""""))), """", INDEX( BEC_openBDF!$A:$D, MATCH( $I12, INDEX( "&" BEC_openBDF!$A:$D, 0, (1 + LEN(REGEXEXTRACT($I12,""^[0-9.]+"")) - LEN(SUBSTITUTE(REGEXEXTRACT($I12,""^[0-9.]+""),""."",""""))) ), 0 ), COLUMN()-9 ) ) )"),"")
I13: 0.1.1.1 Toxic/contaminated material treatment | J13: =IFERROR(__xludf.DUMMYFUNCTION("IF( $I13="""", """", IF( COLUMN()-9 > (1 + LEN(REGEXEXTRACT($I13,""^[0-9.]+"")) - LEN(SUBSTITUTE(REGEXEXTRACT($I13,""^[0-9.]+""),""."",""""))), """", INDEX( BEC_openBDF!$A:$D, MATCH( $I13, INDEX( "&" BEC_openBDF!$A:$D, 0, (1 + LEN(REGEXEXTRACT($I13,""^[0-9.]+"")) - LEN(SUBSTITUTE(REGEXEXTRACT($I13,""^[0-9.]+""),""."",""""))) ), 0 ), COLUMN()-9 ) ) )"),"0 Treatment and demolition works & Facilitating works") -> 0 Treatment and demolition works & Facilitating works | K13: =IFERROR(__xludf.DUMMYFUNCTION("IF( $I13="""", """", IF( COLUMN()-9 > (1 + LEN(REGEXEXTRACT($I13,""^[0-9.]+"")) - LEN(SUBSTITUTE(REGEXEXTRACT($I13,""^[0-9.]+""),""."",""""))), """", INDEX( BEC_openBDF!$A:$D, MATCH( $I13, INDEX( "&" BEC_openBDF!$A:$D, 0, (1 + LEN(REGEXEXTRACT($I13,""^[0-9.]+"")) - LEN(SUBSTITUTE(REGEXEXTRACT($I13,""^[0-9.]+""),""."",""""))) ), 0 ), COLUMN()-9 ) ) )"),"0.1 Treatment and demolition works & Facilitating works") -> 0.1 Treatment and demolition works & Facilitating works | L13: =IFERROR(__xludf.DUMMYFUNCTION("IF( $I13="""", """", IF( COLUMN()-9 > (1 + LEN(REGEXEXTRACT($I13,""^[0-9.]+"")) - LEN(SUBSTITUTE(REGEXEXTRACT($I13,""^[0-9.]+""),""."",""""))), """", INDEX( BEC_openBDF!$A:$D, MATCH( $I13, INDEX( "&" BEC_openBDF!$A:$D, 0, (1 + LEN(REGEXEXTRACT($I13,""^[0-9.]+"")) - LEN(SUBSTITUTE(REGEXEXTRACT($I13,""^[0-9.]+""),""."",""""))) ), 0 ), COLUMN()-9 ) ) )"),"0.1.1 Toxic/contaminated material treatment & Demolition works") -> 0.1.1 Toxic/contaminated material treatment & Demolition works | M13: =IFERROR(__xludf.DUMMYFUNCTION("IF( $I13="""", """", IF( COLUMN()-9 > (1 + LEN(REGEXEXTRACT($I13,""^[0-9.]+"")) - LEN(SUBSTITUTE(REGEXEXTRACT($I13,""^[0-9.]+""),""."",""""))), """", INDEX( BEC_openBDF!$A:$D, MATCH( $I13, INDEX( "&" BEC_openBDF!$A:$D, 0, (1 + LEN(REGEXEXTRACT($I13,""^[0-9.]+"")) - LEN(SUBSTITUTE(REGEXEXTRACT($I13,""^[0-9.]+""),""."",""""))) ), 0 ), COLUMN()-9 ) ) )"),"0.1.1.1 Toxic/contaminated material treatment ") -> 0.1.1.1 Toxic/contaminated material treatment
I14: .. | J14: =IFERROR(__xludf.DUMMYFUNCTION("IF( $I14="""", """", IF( COLUMN()-9 > (1 + LEN(REGEXEXTRACT($I14,""^[0-9.]+"")) - LEN(SUBSTITUTE(REGEXEXTRACT($I14,""^[0-9.]+""),""."",""""))), """", INDEX( BEC_openBDF!$A:$D, MATCH( $I14, INDEX( "&" BEC_openBDF!$A:$D, 0, (1 + LEN(REGEXEXTRACT($I14,""^[0-9.]+"")) - LEN(SUBSTITUTE(REGEXEXTRACT($I14,""^[0-9.]+""),""."",""""))) ), 0 ), COLUMN()-9 ) ) )"),"..") -> .. | K14: =IFERROR(__xludf.DUMMYFUNCTION("IF( $I14="""", """", IF( COLUMN()-9 > (1 + LEN(REGEXEXTRACT($I14,""^[0-9.]+"")) - LEN(SUBSTITUTE(REGEXEXTRACT($I14,""^[0-9.]+""),""."",""""))), """", INDEX( BEC_openBDF!$A:$D, MATCH( $I14, INDEX( "&" BEC_openBDF!$A:$D, 0, (1 + LEN(REGEXEXTRACT($I14,""^[0-9.]+"")) - LEN(SUBSTITUTE(REGEXEXTRACT($I14,""^[0-9.]+""),""."",""""))) ), 0 ), COLUMN()-9 ) ) )"),"..") -> .. | L14: =IFERROR(__xludf.DUMMYFUNCTION("IF( $I14="""", """", IF( COLUMN()-9 > (1 + LEN(REGEXEXTRACT($I14,""^[0-9.]+"")) - LEN(SUBSTITUTE(REGEXEXTRACT($I14,""^[0-9.]+""),""."",""""))), """", INDEX( BEC_openBDF!$A:$D, MATCH( $I14, INDEX( "&" BEC_openBDF!$A:$D, 0, (1 + LEN(REGEXEXTRACT($I14,""^[0-9.]+"")) - LEN(SUBSTITUTE(REGEXEXTRACT($I14,""^[0-9.]+""),""."",""""))) ), 0 ), COLUMN()-9 ) ) )"),"..") -> .. | M14: =IFERROR(__xludf.DUMMYFUNCTION("IF( $I14="""", """", IF( COLUMN()-9 > (1 + LEN(REGEXEXTRACT($I14,""^[0-9.]+"")) - LEN(SUBSTITUTE(REGEXEXTRACT($I14,""^[0-9.]+""),""."",""""))), """", INDEX( BEC_openBDF!$A:$D, MATCH( $I14, INDEX( "&" BEC_openBDF!$A:$D, 0, (1 + LEN(REGEXEXTRACT($I14,""^[0-9.]+"")) - LEN(SUBSTITUTE(REGEXEXTRACT($I14,""^[0-9.]+""),""."",""""))) ), 0 ), COLUMN()-9 ) ) )"),"")
I15: .. | J15: =IFERROR(__xludf.DUMMYFUNCTION("IF( $I15="""", """", IF( COLUMN()-9 > (1 + LEN(REGEXEXTRACT($I15,""^[0-9.]+"")) - LEN(SUBSTITUTE(REGEXEXTRACT($I15,""^[0-9.]+""),""."",""""))), """", INDEX( BEC_openBDF!$A:$D, MATCH( $I15, INDEX( "&" BEC_openBDF!$A:$D, 0, (1 + LEN(REGEXEXTRACT($I15,""^[0-9.]+"")) - LEN(SUBSTITUTE(REGEXEXTRACT($I15,""^[0-9.]+""),""."",""""))) ), 0 ), COLUMN()-9 ) ) )"),"..") -> .. | K15: =IFERROR(__xludf.DUMMYFUNCTION("IF( $I15="""", """", IF( COLUMN()-9 > (1 + LEN(REGEXEXTRACT($I15,""^[0-9.]+"")) - LEN(SUBSTITUTE(REGEXEXTRACT($I15,""^[0-9.]+""),""."",""""))), """", INDEX( BEC_openBDF!$A:$D, MATCH( $I15, INDEX( "&" BEC_openBDF!$A:$D, 0, (1 + LEN(REGEXEXTRACT($I15,""^[0-9.]+"")) - LEN(SUBSTITUTE(REGEXEXTRACT($I15,""^[0-9.]+""),""."",""""))) ), 0 ), COLUMN()-9 ) ) )"),"..") -> .. | L15: =IFERROR(__xludf.DUMMYFUNCTION("IF( $I15="""", """", IF( COLUMN()-9 > (1 + LEN(REGEXEXTRACT($I15,""^[0-9.]+"")) - LEN(SUBSTITUTE(REGEXEXTRACT($I15,""^[0-9.]+""),""."",""""))), """", INDEX( BEC_openBDF!$A:$D, MATCH( $I15, INDEX( "&" BEC_openBDF!$A:$D, 0, (1 + LEN(REGEXEXTRACT($I15,""^[0-9.]+"")) - LEN(SUBSTITUTE(REGEXEXTRACT($I15,""^[0-9.]+""),""."",""""))) ), 0 ), COLUMN()-9 ) ) )"),"..") -> .. | M15: =IFERROR(__xludf.DUMMYFUNCTION("IF( $I15="""", """", IF( COLUMN()-9 > (1 + LEN(REGEXEXTRACT($I15,""^[0-9.]+"")) - LEN(SUBSTITUTE(REGEXEXTRACT($I15,""^[0-9.]+""),""."",""""))), """", INDEX( BEC_openBDF!$A:$D, MATCH( $I15, INDEX( "&" BEC_openBDF!$A:$D, 0, (1 + LEN(REGEXEXTRACT($I15,""^[0-9.]+"")) - LEN(SUBSTITUTE(REGEXEXTRACT($I15,""^[0-9.]+""),""."",""""))) ), 0 ), COLUMN()-9 ) ) )"),"")
I68: .. | J68: =IFERROR(__xludf.DUMMYFUNCTION("IF( $I68="""", """", IF( COLUMN()-9 > (1 + LEN(REGEXEXTRACT($I68,""^[0-9.]+"")) - LEN(SUBSTITUTE(REGEXEXTRACT($I68,""^[0-9.]+""),""."",""""))), """", INDEX( BEC_openBDF!$A:$D, MATCH( $I68, INDEX( "&" BEC_openBDF!$A:$D, 0, (1 + LEN(REGEXEXTRACT($I68,""^[0-9.]+"")) - LEN(SUBSTITUTE(REGEXEXTRACT($I68,""^[0-9.]+""),""."",""""))) ), 0 ), COLUMN()-9 ) ) )"),"..") -> .. | K68: =IFERROR(__xludf.DUMMYFUNCTION("IF( $I68="""", """", IF( COLUMN()-9 > (1 + LEN(REGEXEXTRACT($I68,""^[0-9.]+"")) - LEN(SUBSTITUTE(REGEXEXTRACT($I68,""^[0-9.]+""),""."",""""))), """", INDEX( BEC_openBDF!$A:$D, MATCH( $I68, INDEX( "&" BEC_openBDF!$A:$D, 0, (1 + LEN(REGEXEXTRACT($I68,""^[0-9.]+"")) - LEN(SUBSTITUTE(REGEXEXTRACT($I68,""^[0-9.]+""),""."",""""))) ), 0 ), COLUMN()-9 ) ) )"),"..") -> .. | L68: =IFERROR(__xludf.DUMMYFUNCTION("IF( $I68="""", """", IF( COLUMN()-9 > (1 + LEN(REGEXEXTRACT($I68,""^[0-9.]+"")) - LEN(SUBSTITUTE(REGEXEXTRACT($I68,""^[0-9.]+""),""."",""""))), """", INDEX( BEC_openBDF!$A:$D, MATCH( $I68, INDEX( "&" BEC_openBDF!$A:$D, 0, (1 + LEN(REGEXEXTRACT($I68,""^[0-9.]+"")) - LEN(SUBSTITUTE(REGEXEXTRACT($I68,""^[0-9.]+""),""."",""""))) ), 0 ), COLUMN()-9 ) ) )"),"..") -> .. | M68: =IFERROR(__xludf.DUMMYFUNCTION("IF( $I68="""", """", IF( COLUMN()-9 > (1 + LEN(REGEXEXTRACT($I68,""^[0-9.]+"")) - LEN(SUBSTITUTE(REGEXEXTRACT($I68,""^[0-9.]+""),""."",""""))), """", INDEX( BEC_openBDF!$A:$D, MATCH( $I68, INDEX( "&" BEC_openBDF!$A:$D, 0, (1 + LEN(REGEXEXTRACT($I68,""^[0-9.]+"")) - LEN(SUBSTITUTE(REGEXEXTRACT($I68,""^[0-9.]+""),""."",""""))) ), 0 ), COLUMN()-9 ) ) )"),"")
I69: .. | J69: =IFERROR(__xludf.DUMMYFUNCTION("IF( $I69="""", """", IF( COLUMN()-9 > (1 + LEN(REGEXEXTRACT($I69,""^[0-9.]+"")) - LEN(SUBSTITUTE(REGEXEXTRACT($I69,""^[0-9.]+""),""."",""""))), """", INDEX( BEC_openBDF!$A:$D, MATCH( $I69, INDEX( "&" BEC_openBDF!$A:$D, 0, (1 + LEN(REGEXEXTRACT($I69,""^[0-9.]+"")) - LEN(SUBSTITUTE(REGEXEXTRACT($I69,""^[0-9.]+""),""."",""""))) ), 0 ), COLUMN()-9 ) ) )"),"..") -> .. | K69: =IFERROR(__xludf.DUMMYFUNCTION("IF( $I69="""", """", IF( COLUMN()-9 > (1 + LEN(REGEXEXTRACT($I69,""^[0-9.]+"")) - LEN(SUBSTITUTE(REGEXEXTRACT($I69,""^[0-9.]+""),""."",""""))), """", INDEX( BEC_openBDF!$A:$D, MATCH( $I69, INDEX( "&" BEC_openBDF!$A:$D, 0, (1 + LEN(REGEXEXTRACT($I69,""^[0-9.]+"")) - LEN(SUBSTITUTE(REGEXEXTRACT($I69,""^[0-9.]+""),""."",""""))) ), 0 ), COLUMN()-9 ) ) )"),"..") -> .. | L69: =IFERROR(__xludf.DUMMYFUNCTION("IF( $I69="""", """", IF( COLUMN()-9 > (1 + LEN(REGEXEXTRACT($I69,""^[0-9.]+"")) - LEN(SUBSTITUTE(REGEXEXTRACT($I69,""^[0-9.]+""),""."",""""))), """", INDEX( BEC_openBDF!$A:$D, MATCH( $I69, INDEX( "&" BEC_openBDF!$A:$D, 0, (1 + LEN(REGEXEXTRACT($I69,""^[0-9.]+"")) - LEN(SUBSTITUTE(REGEXEXTRACT($I69,""^[0-9.]+""),""."",""""))) ), 0 ), COLUMN()-9 ) ) )"),"..") -> .. | M69: =IFERROR(__xludf.DUMMYFUNCTION("IF( $I69="""", """", IF( COLUMN()-9 > (1 + LEN(REGEXEXTRACT($I69,""^[0-9.]+"")) - LEN(SUBSTITUTE(REGEXEXTRACT($I69,""^[0-9.]+""),""."",""""))), """", INDEX( BEC_openBDF!$A:$D, MATCH( $I69, INDEX( "&" BEC_openBDF!$A:$D, 0, (1 + LEN(REGEXEXTRACT($I69,""^[0-9.]+"")) - LEN(SUBSTITUTE(REGEXEXTRACT($I69,""^[0-9.]+""),""."",""""))) ), 0 ), COLUMN()-9 ) ) )"),"")
I70: .. | J70: =IFERROR(__xludf.DUMMYFUNCTION("IF( $I70="""", """", IF( COLUMN()-9 > (1 + LEN(REGEXEXTRACT($I70,""^[0-9.]+"")) - LEN(SUBSTITUTE(REGEXEXTRACT($I70,""^[0-9.]+""),""."",""""))), """", INDEX( BEC_openBDF!$A:$D, MATCH( $I70, INDEX( "&" BEC_openBDF!$A:$D, 0, (1 + LEN(REGEXEXTRACT($I70,""^[0-9.]+"")) - LEN(SUBSTITUTE(REGEXEXTRACT($I70,""^[0-9.]+""),""."",""""))) ), 0 ), COLUMN()-9 ) ) )"),"..") -> .. | K70: =IFERROR(__xludf.DUMMYFUNCTION("IF( $I70="""", """", IF( COLUMN()-9 > (1 + LEN(REGEXEXTRACT($I70,""^[0-9.]+"")) - LEN(SUBSTITUTE(REGEXEXTRACT($I70,""^[0-9.]+""),""."",""""))), """", INDEX( BEC_openBDF!$A:$D, MATCH( $I70, INDEX( "&" BEC_openBDF!$A:$D, 0, (1 + LEN(REGEXEXTRACT($I70,""^[0-9.]+"")) - LEN(SUBSTITUTE(REGEXEXTRACT($I70,""^[0-9.]+""),""."",""""))) ), 0 ), COLUMN()-9 ) ) )"),"..") -> .. | L70: =IFERROR(__xludf.DUMMYFUNCTION("IF( $I70="""", """", IF( COLUMN()-9 > (1 + LEN(REGEXEXTRACT($I70,""^[0-9.]+"")) - LEN(SUBSTITUTE(REGEXEXTRACT($I70,""^[0-9.]+""),""."",""""))), """", INDEX( BEC_openBDF!$A:$D, MATCH( $I70, INDEX( "&" BEC_openBDF!$A:$D, 0, (1 + LEN(REGEXEXTRACT($I70,""^[0-9.]+"")) - LEN(SUBSTITUTE(REGEXEXTRACT($I70,""^[0-9.]+""),""."",""""))) ), 0 ), COLUMN()-9 ) ) )"),"..") -> .. | M70: =IFERROR(__xludf.DUMMYFUNCTION("IF( $I70="""", """", IF( COLUMN()-9 > (1 + LEN(REGEXEXTRACT($I70,""^[0-9.]+"")) - LEN(SUBSTITUTE(REGEXEXTRACT($I70,""^[0-9.]+""),""."",""""))), """", INDEX( BEC_openBDF!$A:$D, MATCH( $I70, INDEX( "&" BEC_openBDF!$A:$D, 0, (1 + LEN(REGEXEXTRACT($I70,""^[0-9.]+"")) - LEN(SUBSTITUTE(REGEXEXTRACT($I70,""^[0-9.]+""),""."",""""))) ), 0 ), COLUMN()-9 ) ) )"),"")
I71: .. | J71: =IFERROR(__xludf.DUMMYFUNCTION("IF( $I71="""", """", IF( COLUMN()-9 > (1 + LEN(REGEXEXTRACT($I71,""^[0-9.]+"")) - LEN(SUBSTITUTE(REGEXEXTRACT($I71,""^[0-9.]+""),""."",""""))), """", INDEX( BEC_openBDF!$A:$D, MATCH( $I71, INDEX( "&" BEC_openBDF!$A:$D, 0, (1 + LEN(REGEXEXTRACT($I71,""^[0-9.]+"")) - LEN(SUBSTITUTE(REGEXEXTRACT($I71,""^[0-9.]+""),""."",""""))) ), 0 ), COLUMN()-9 ) ) )"),"..") -> .. | K71: =IFERROR(__xludf.DUMMYFUNCTION("IF( $I71="""", """", IF( COLUMN()-9 > (1 + LEN(REGEXEXTRACT($I71,""^[0-9.]+"")) - LEN(SUBSTITUTE(REGEXEXTRACT($I71,""^[0-9.]+""),""."",""""))), """", INDEX( BEC_openBDF!$A:$D, MATCH( $I71, INDEX( "&" BEC_openBDF!$A:$D, 0, (1 + LEN(REGEXEXTRACT($I71,""^[0-9.]+"")) - LEN(SUBSTITUTE(REGEXEXTRACT($I71,""^[0-9.]+""),""."",""""))) ), 0 ), COLUMN()-9 ) ) )"),"..") -> .. | L71: =IFERROR(__xludf.DUMMYFUNCTION("IF( $I71="""", """", IF( COLUMN()-9 > (1 + LEN(REGEXEXTRACT($I71,""^[0-9.]+"")) - LEN(SUBSTITUTE(REGEXEXTRACT($I71,""^[0-9.]+""),""."",""""))), """", INDEX( BEC_openBDF!$A:$D, MATCH( $I71, INDEX( "&" BEC_openBDF!$A:$D, 0, (1 + LEN(REGEXEXTRACT($I71,""^[0-9.]+"")) - LEN(SUBSTITUTE(REGEXEXTRACT($I71,""^[0-9.]+""),""."",""""))) ), 0 ), COLUMN()-9 ) ) )"),"..") -> .. | M71: =IFERROR(__xludf.DUMMYFUNCTION("IF( $I71="""", """", IF( COLUMN()-9 > (1 + LEN(REGEXEXTRACT($I71,""^[0-9.]+"")) - LEN(SUBSTITUTE(REGEXEXTRACT($I71,""^[0-9.]+""),""."",""""))), """", INDEX( BEC_openBDF!$A:$D, MATCH( $I71, INDEX( "&" BEC_openBDF!$A:$D, 0, (1 + LEN(REGEXEXTRACT($I71,""^[0-9.]+"")) - LEN(SUBSTITUTE(REGEXEXTRACT($I71,""^[0-9.]+""),""."",""""))) ), 0 ), COLUMN()-9 ) ) )"),"")
I72: .. | J72: =IFERROR(__xludf.DUMMYFUNCTION("IF( $I72="""", """", IF( COLUMN()-9 > (1 + LEN(REGEXEXTRACT($I72,""^[0-9.]+"")) - LEN(SUBSTITUTE(REGEXEXTRACT($I72,""^[0-9.]+""),""."",""""))), """", INDEX( BEC_openBDF!$A:$D, MATCH( $I72, INDEX( "&" BEC_openBDF!$A:$D, 0, (1 + LEN(REGEXEXTRACT($I72,""^[0-9.]+"")) - LEN(SUBSTITUTE(REGEXEXTRACT($I72,""^[0-9.]+""),""."",""""))) ), 0 ), COLUMN()-9 ) ) )"),"..") -> .. | K72: =IFERROR(__xludf.DUMMYFUNCTION("IF( $I72="""", """", IF( COLUMN()-9 > (1 + LEN(REGEXEXTRACT($I72,""^[0-9.]+"")) - LEN(SUBSTITUTE(REGEXEXTRACT($I72,""^[0-9.]+""),""."",""""))), """", INDEX( BEC_openBDF!$A:$D, MATCH( $I72, INDEX( "&" BEC_openBDF!$A:$D, 0, (1 + LEN(REGEXEXTRACT($I72,""^[0-9.]+"")) - LEN(SUBSTITUTE(REGEXEXTRACT($I72,""^[0-9.]+""),""."",""""))) ), 0 ), COLUMN()-9 ) ) )"),"..") -> .. | L72: =IFERROR(__xludf.DUMMYFUNCTION("IF( $I72="""", """", IF( COLUMN()-9 > (1 + LEN(REGEXEXTRACT($I72,""^[0-9.]+"")) - LEN(SUBSTITUTE(REGEXEXTRACT($I72,""^[0-9.]+""),""."",""""))), """", INDEX( BEC_openBDF!$A:$D, MATCH( $I72, INDEX( "&" BEC_openBDF!$A:$D, 0, (1 + LEN(REGEXEXTRACT($I72,""^[0-9.]+"")) - LEN(SUBSTITUTE(REGEXEXTRACT($I72,""^[0-9.]+""),""."",""""))) ), 0 ), COLUMN()-9 ) ) )"),"..") -> .. | M72: =IFERROR(__xludf.DUMMYFUNCTION("IF( $I72="""", """", IF( COLUMN()-9 > (1 + LEN(REGEXEXTRACT($I72,""^[0-9.]+"")) - LEN(SUBSTITUTE(REGEXEXTRACT($I72,""^[0-9.]+""),""."",""""))), """", INDEX( BEC_openBDF!$A:$D, MATCH( $I72, INDEX( "&" BEC_openBDF!$A:$D, 0, (1 + LEN(REGEXEXTRACT($I72,""^[0-9.]+"")) - LEN(SUBSTITUTE(REGEXEXTRACT($I72,""^[0-9.]+""),""."",""""))) ), 0 ), COLUMN()-9 ) ) )"),"")
I73: .. | J73: =IFERROR(__xludf.DUMMYFUNCTION("IF( $I73="""", """", IF( COLUMN()-9 > (1 + LEN(REGEXEXTRACT($I73,""^[0-9.]+"")) - LEN(SUBSTITUTE(REGEXEXTRACT($I73,""^[0-9.]+""),""."",""""))), """", INDEX( BEC_openBDF!$A:$D, MATCH( $I73, INDEX( "&" BEC_openBDF!$A:$D, 0, (1 + LEN(REGEXEXTRACT($I73,""^[0-9.]+"")) - LEN(SUBSTITUTE(REGEXEXTRACT($I73,""^[0-9.]+""),""."",""""))) ), 0 ), COLUMN()-9 ) ) )"),"..") -> .. | K73: =IFERROR(__xludf.DUMMYFUNCTION("IF( $I73="""", """", IF( COLUMN()-9 > (1 + LEN(REGEXEXTRACT($I73,""^[0-9.]+"")) - LEN(SUBSTITUTE(REGEXEXTRACT($I73,""^[0-9.]+""),""."",""""))), """", INDEX( BEC_openBDF!$A:$D, MATCH( $I73, INDEX( "&" BEC_openBDF!$A:$D, 0, (1 + LEN(REGEXEXTRACT($I73,""^[0-9.]+"")) - LEN(SUBSTITUTE(REGEXEXTRACT($I73,""^[0-9.]+""),""."",""""))) ), 0 ), COLUMN()-9 ) ) )"),"..") -> .. | L73: =IFERROR(__xludf.DUMMYFUNCTION("IF( $I73="""", """", IF( COLUMN()-9 > (1 + LEN(REGEXEXTRACT($I73,""^[0-9.]+"")) - LEN(SUBSTITUTE(REGEXEXTRACT($I73,""^[0-9.]+""),""."",""""))), """", INDEX( BEC_openBDF!$A:$D, MATCH( $I73, INDEX( "&" BEC_openBDF!$A:$D, 0, (1 + LEN(REGEXEXTRACT($I73,""^[0-9.]+"")) - LEN(SUBSTITUTE(REGEXEXTRACT($I73,""^[0-9.]+""),""."",""""))) ), 0 ), COLUMN()-9 ) ) )"),"..") -> .. | M73: =IFERROR(__xludf.DUMMYFUNCTION("IF( $I73="""", """", IF( COLUMN()-9 > (1 + LEN(REGEXEXTRACT($I73,""^[0-9.]+"")) - LEN(SUBSTITUTE(REGEXEXTRACT($I73,""^[0-9.]+""),""."",""""))), """", INDEX( BEC_openBDF!$A:$D, MATCH( $I73, INDEX( "&" BEC_openBDF!$A:$D, 0, (1 + LEN(REGEXEXTRACT($I73,""^[0-9.]+"")) - LEN(SUBSTITUTE(REGEXEXTRACT($I73,""^[0-9.]+""),""."",""""))) ), 0 ), COLUMN()-9 ) ) )"),"")
I74: .. | J74: =IFERROR(__xludf.DUMMYFUNCTION("IF( $I74="""", """", IF( COLUMN()-9 > (1 + LEN(REGEXEXTRACT($I74,""^[0-9.]+"")) - LEN(SUBSTITUTE(REGEXEXTRACT($I74,""^[0-9.]+""),""."",""""))), """", INDEX( BEC_openBDF!$A:$D, MATCH( $I74, INDEX( "&" BEC_openBDF!$A:$D, 0, (1 + LEN(REGEXEXTRACT($I74,""^[0-9.]+"")) - LEN(SUBSTITUTE(REGEXEXTRACT($I74,""^[0-9.]+""),""."",""""))) ), 0 ), COLUMN()-9 ) ) )"),"..") -> .. | K74: =IFERROR(__xludf.DUMMYFUNCTION("IF( $I74="""", """", IF( COLUMN()-9 > (1 + LEN(REGEXEXTRACT($I74,""^[0-9.]+"")) - LEN(SUBSTITUTE(REGEXEXTRACT($I74,""^[0-9.]+""),""."",""""))), """", INDEX( BEC_openBDF!$A:$D, MATCH( $I74, INDEX( "&" BEC_openBDF!$A:$D, 0, (1 + LEN(REGEXEXTRACT($I74,""^[0-9.]+"")) - LEN(SUBSTITUTE(REGEXEXTRACT($I74,""^[0-9.]+""),""."",""""))) ), 0 ), COLUMN()-9 ) ) )"),"..") -> .. | L74: =IFERROR(__xludf.DUMMYFUNCTION("IF( $I74="""", """", IF( COLUMN()-9 > (1 + LEN(REGEXEXTRACT($I74,""^[0-9.]+"")) - LEN(SUBSTITUTE(REGEXEXTRACT($I74,""^[0-9.]+""),""."",""""))), """", INDEX( BEC_openBDF!$A:$D, MATCH( $I74, INDEX( "&" BEC_openBDF!$A:$D, 0, (1 + LEN(REGEXEXTRACT($I74,""^[0-9.]+"")) - LEN(SUBSTITUTE(REGEXEXTRACT($I74,""^[0-9.]+""),""."",""""))) ), 0 ), COLUMN()-9 ) ) )"),"..") -> .. | M74: =IFERROR(__xludf.DUMMYFUNCTION("IF( $I74="""", """", IF( COLUMN()-9 > (1 + LEN(REGEXEXTRACT($I74,""^[0-9.]+"")) - LEN(SUBSTITUTE(REGEXEXTRACT($I74,""^[0-9.]+""),""."",""""))), """", INDEX( BEC_openBDF!$A:$D, MATCH( $I74, INDEX( "&" BEC_openBDF!$A:$D, 0, (1 + LEN(REGEXEXTRACT($I74,""^[0-9.]+"")) - LEN(SUBSTITUTE(REGEXEXTRACT($I74,""^[0-9.]+""),""."",""""))) ), 0 ), COLUMN()-9 ) ) )"),"")
I75: .. | J75: =IFERROR(__xludf.DUMMYFUNCTION("IF( $I75="""", """", IF( COLUMN()-9 > (1 + LEN(REGEXEXTRACT($I75,""^[0-9.]+"")) - LEN(SUBSTITUTE(REGEXEXTRACT($I75,""^[0-9.]+""),""."",""""))), """", INDEX( BEC_openBDF!$A:$D, MATCH( $I75, INDEX( "&" BEC_openBDF!$A:$D, 0, (1 + LEN(REGEXEXTRACT($I75,""^[0-9.]+"")) - LEN(SUBSTITUTE(REGEXEXTRACT($I75,""^[0-9.]+""),""."",""""))) ), 0 ), COLUMN()-9 ) ) )"),"..") -> .. | K75: =IFERROR(__xludf.DUMMYFUNCTION("IF( $I75="""", """", IF( COLUMN()-9 > (1 + LEN(REGEXEXTRACT($I75,""^[0-9.]+"")) - LEN(SUBSTITUTE(REGEXEXTRACT($I75,""^[0-9.]+""),""."",""""))), """", INDEX( BEC_openBDF!$A:$D, MATCH( $I75, INDEX( "&" BEC_openBDF!$A:$D, 0, (1 + LEN(REGEXEXTRACT($I75,""^[0-9.]+"")) - LEN(SUBSTITUTE(REGEXEXTRACT($I75,""^[0-9.]+""),""."",""""))) ), 0 ), COLUMN()-9 ) ) )"),"..") -> .. | L75: =IFERROR(__xludf.DUMMYFUNCTION("IF( $I75="""", """", IF( COLUMN()-9 > (1 + LEN(REGEXEXTRACT($I75,""^[0-9.]+"")) - LEN(SUBSTITUTE(REGEXEXTRACT($I75,""^[0-9.]+""),""."",""""))), """", INDEX( BEC_openBDF!$A:$D, MATCH( $I75, INDEX( "&" BEC_openBDF!$A:$D, 0, (1 + LEN(REGEXEXTRACT($I75,""^[0-9.]+"")) - LEN(SUBSTITUTE(REGEXEXTRACT($I75,""^[0-9.]+""),""."",""""))) ), 0 ), COLUMN()-9 ) ) )"),"..") -> .. | M75: =IFERROR(__xludf.DUMMYFUNCTION("IF( $I75="""", """", IF( COLUMN()-9 > (1 + LEN(REGEXEXTRACT($I75,""^[0-9.]+"")) - LEN(SUBSTITUTE(REGEXEXTRACT($I75,""^[0-9.]+""),""."",""""))), """", INDEX( BEC_openBDF!$A:$D, MATCH( $I75, INDEX( "&" BEC_openBDF!$A:$D, 0, (1 + LEN(REGEXEXTRACT($I75,""^[0-9.]+"")) - LEN(SUBSTITUTE(REGEXEXTRACT($I75,""^[0-9.]+""),""."",""""))) ), 0 ), COLUMN()-9 ) ) )"),"")
I76: .. | J76: =IFERROR(__xludf.DUMMYFUNCTION("IF( $I76="""", """", IF( COLUMN()-9 > (1 + LEN(REGEXEXTRACT($I76,""^[0-9.]+"")) - LEN(SUBSTITUTE(REGEXEXTRACT($I76,""^[0-9.]+""),""."",""""))), """", INDEX( BEC_openBDF!$A:$D, MATCH( $I76, INDEX( "&" BEC_openBDF!$A:$D, 0, (1 + LEN(REGEXEXTRACT($I76,""^[0-9.]+"")) - LEN(SUBSTITUTE(REGEXEXTRACT($I76,""^[0-9.]+""),""."",""""))) ), 0 ), COLUMN()-9 ) ) )"),"..") -> .. | K76: =IFERROR(__xludf.DUMMYFUNCTION("IF( $I76="""", """", IF( COLUMN()-9 > (1 + LEN(REGEXEXTRACT($I76,""^[0-9.]+"")) - LEN(SUBSTITUTE(REGEXEXTRACT($I76,""^[0-9.]+""),""."",""""))), """", INDEX( BEC_openBDF!$A:$D, MATCH( $I76, INDEX( "&" BEC_openBDF!$A:$D, 0, (1 + LEN(REGEXEXTRACT($I76,""^[0-9.]+"")) - LEN(SUBSTITUTE(REGEXEXTRACT($I76,""^[0-9.]+""),""."",""""))) ), 0 ), COLUMN()-9 ) ) )"),"..") -> .. | L76: =IFERROR(__xludf.DUMMYFUNCTION("IF( $I76="""", """", IF( COLUMN()-9 > (1 + LEN(REGEXEXTRACT($I76,""^[0-9.]+"")) - LEN(SUBSTITUTE(REGEXEXTRACT($I76,""^[0-9.]+""),""."",""""))), """", INDEX( BEC_openBDF!$A:$D, MATCH( $I76, INDEX( "&" BEC_openBDF!$A:$D, 0, (1 + LEN(REGEXEXTRACT($I76,""^[0-9.]+"")) - LEN(SUBSTITUTE(REGEXEXTRACT($I76,""^[0-9.]+""),""."",""""))) ), 0 ), COLUMN()-9 ) ) )"),"..") -> .. | M76: =IFERROR(__xludf.DUMMYFUNCTION("IF( $I76="""", """", IF( COLUMN()-9 > (1 + LEN(REGEXEXTRACT($I76,""^[0-9.]+"")) - LEN(SUBSTITUTE(REGEXEXTRACT($I76,""^[0-9.]+""),""."",""""))), """", INDEX( BEC_openBDF!$A:$D, MATCH( $I76, INDEX( "&" BEC_openBDF!$A:$D, 0, (1 + LEN(REGEXEXTRACT($I76,""^[0-9.]+"")) - LEN(SUBSTITUTE(REGEXEXTRACT($I76,""^[0-9.]+""),""."",""""))) ), 0 ), COLUMN()-9 ) ) )"),"")
I77: .. | J77: =IFERROR(__xludf.DUMMYFUNCTION("IF( $I77="""", """", IF( COLUMN()-9 > (1 + LEN(REGEXEXTRACT($I77,""^[0-9.]+"")) - LEN(SUBSTITUTE(REGEXEXTRACT($I77,""^[0-9.]+""),""."",""""))), """", INDEX( BEC_openBDF!$A:$D, MATCH( $I77, INDEX( "&" BEC_openBDF!$A:$D, 0, (1 + LEN(REGEXEXTRACT($I77,""^[0-9.]+"")) - LEN(SUBSTITUTE(REGEXEXTRACT($I77,""^[0-9.]+""),""."",""""))) ), 0 ), COLUMN()-9 ) ) )"),"..") -> .. | K77: =IFERROR(__xludf.DUMMYFUNCTION("IF( $I77="""", """", IF( COLUMN()-9 > (1 + LEN(REGEXEXTRACT($I77,""^[0-9.]+"")) - LEN(SUBSTITUTE(REGEXEXTRACT($I77,""^[0-9.]+""),""."",""""))), """", INDEX( BEC_openBDF!$A:$D, MATCH( $I77, INDEX( "&" BEC_openBDF!$A:$D, 0, (1 + LEN(REGEXEXTRACT($I77,""^[0-9.]+"")) - LEN(SUBSTITUTE(REGEXEXTRACT($I77,""^[0-9.]+""),""."",""""))) ), 0 ), COLUMN()-9 ) ) )"),"..") -> .. | L77: =IFERROR(__xludf.DUMMYFUNCTION("IF( $I77="""", """", IF( COLUMN()-9 > (1 + LEN(REGEXEXTRACT($I77,""^[0-9.]+"")) - LEN(SUBSTITUTE(REGEXEXTRACT($I77,""^[0-9.]+""),""."",""""))), """", INDEX( BEC_openBDF!$A:$D, MATCH( $I77, INDEX( "&" BEC_openBDF!$A:$D, 0, (1 + LEN(REGEXEXTRACT($I77,""^[0-9.]+"")) - LEN(SUBSTITUTE(REGEXEXTRACT($I77,""^[0-9.]+""),""."",""""))) ), 0 ), COLUMN()-9 ) ) )"),"..") -> .. | M77: =IFERROR(__xludf.DUMMYFUNCTION("IF( $I77="""", """", IF( COLUMN()-9 > (1 + LEN(REGEXEXTRACT($I77,""^[0-9.]+"")) - LEN(SUBSTITUTE(REGEXEXTRACT($I77,""^[0-9.]+""),""."",""""))), """", INDEX( BEC_openBDF!$A:$D, MATCH( $I77, INDEX( "&" BEC_openBDF!$A:$D, 0, (1 + LEN(REGEXEXTRACT($I77,""^[0-9.]+"")) - LEN(SUBSTITUTE(REGEXEXTRACT($I77,""^[0-9.]+""),""."",""""))) ), 0 ), COLUMN()-9 ) ) )"),"")
